Workbook

Sheet Molecules_Negative-ion mode
F1: 群検出率 | G1: 0.8 | U1: =(AD1-1)/(AD1+1) -> -1 | V1: =(#REF!-1)/(#REF!+1) -> #REF! | W1: =(AH1-1)/(AH1+1) -> -1 | AN1: Control | AV1: HFpEF | BD1: B
I2: Control | J2: Control | K2: Control | L2: Control | M2: Control | N2: Control | O2: Control | Q2: HFpEF | R2: HFpEF | S2: HFpEF | T2: HFpEF | U2: HFpEF | V2: HFpEF | W2: HFpEF | Y2: Blank | Z2: QC | AA2: QC | AB2: QC | AC2: QC | AD2: Mean | AG2: Welch-T | AK2: 平滑化前 | AL2: FDR | AN2: 1 | AO2: 2 | AP2: 3 | AQ2: 4 | AR2: 5 | AS2: 6 | AT2: 7 | AV2: 8 | AW2: 9 | AX2: 1 | AY2: 1 | AZ2: 1 | BA2: 1 | BB2: 1 | BD2: l
A3: Polarity | B3: index | C3: m/z | D3: rt | E3: z | F3: Annotation | G3: Class | H3: コメント | I3: 1 | J3: 2 | K3: 3 | L3: 4 | M3: 5 | N3: 6 | O3: 7 | Q3: 8 | R3: 9 | S3: 10 | T3: 11 | U3: 12 | V3: 13 | W3: 14 | Y3: Blank | Z3: 1 | AA3: 2 | AB3: 3 | AC3: RSD | AD3: Control | AE3: HFpEF | AF3: Fold change | AG3: P-value | AH3: Significance | AI3: 検定数 | AJ3: =COUNT(AJ4:AJ390) -> 387 | AK3: Q値 | AL3: Q-value | AM3: Significance | AX3: 0 | AY3: 1 | AZ3: 2 | BA3: 3 | BB3: 4 | BD3: k
A4: Neg | B4: 49 | C4: 279.23264 | D4: 5.0156037 | E4: -1 | F4: FA(18:2) | G4: FA | I4: 73974 | J4: 47087 | K4: 38699 | L4: 27618 | M4: 43138 | N4: 62619 | O4: 58251 | Q4: 35283 | R4: 105765 | S4: 48590 | T4: 44918 | U4: 107356 | V4: 42508 | W4: 69438 | Y4: 2410 | Z4: 56518 | AA4: 70359 | AB4: 68640 | AC4: =IFERROR(STDEV(Z4:AB4)/AVERAGE(Z4:AB4),0) -> 0.11575456 | AD4: =AVERAGE(I4:O4) -> 50198 | AE4: =AVERAGE(Q4:W4) -> 64836.857 | AF4: =AE4/AD4 -> 1.2916223 | AG4: =TTEST(I4:O4,Q4:W4,2,3) -> 0.2868518 | AH4: =IF(AG4<0.001,"***",IF(AG4<0.01,"**",IF(AG4<0.05,"*","-"))) -> - | AI4: =_xlfn.RANK.EQ(AG4,$AG$4:$AG$390,1) -> 272 | AJ4: =COUNTIF($AI$4:$AI$390,AI4)+AI4-1 -> 272 | AK4: =MIN(AG4*$AJ$3/AJ4,1) -> 0.40813105 | AL4: =MIN(AK4,IFERROR(VLOOKUP(AJ4+1,$AJ$4:$AL$390,3,FALSE),1)) -> 0.40813105 | AM4: =IF(AL4<0.05,"**",IF(AL4<0.1,"*",""))
A5: Neg | B5: 61 | C5: 281.24841 | D5: 5.4776324 | E5: -1 | F5: FA(18:1) | G5: FA | I5: 32894 | J5: 27780 | K5: 25971 | L5: 29617 | M5: 32858 | N5: 44821 | O5: 33859 | Q5: 37438 | R5: 79389 | S5: 37908 | T5: 38144 | U5: 64735 | V5: 30332 | W5: 51618 | Y5: 15746 | Z5: 47374 | AA5: 44288 | AB5: 46473 | AC5: =IFERROR(STDEV(Z5:AB5)/AVERAGE(Z5:AB5),0) -> 0.034464011 | AD5: =AVERAGE(I5:O5) -> 32542.857 | AE5: =AVERAGE(Q5:W5) -> 48509.143 | AF5: =AE5/AD5 -> 1.4906234 | AG5: =TTEST(I5:O5,Q5:W5,2,3) -> 0.057649653 | AH5: =IF(AG5<0.001,"***",IF(AG5<0.01,"**",IF(AG5<0.05,"*","-"))) -> - | AI5: =_xlfn.RANK.EQ(AG5,$AG$4:$AG$390,1) -> 167 | AJ5: =COUNTIF($AI$4:$AI$390,AI5)+AI5-1 -> 167 | AK5: =MIN(AG5*$AJ$3/AJ5,1) -> 0.1335953 | AL5: =MIN(AK5,IFERROR(VLOOKUP(AJ5+1,$AJ$4:$AL$390,3,FALSE),1)) -> 0.1335953 | AM5: =IF(AL5<0.05,"**",IF(AL5<0.1,"*",""))
A6: Neg | B6: 68 | C6: 327.23226 | D6: 4.8707696 | E6: -1 | F6: FA(22:6) | G6: FA | I6: 21433 | J6: 20510 | K6: 22346 | L6: 10996 | M6: 12124 | N6: 24652 | O6: 18319 | Q6: 27519 | R6: 69675 | S6: 50293 | T6: 37443 | U6: 50794 | V6: 44835 | W6: 63731 | Y6: 4 | Z6: 25980 | AA6: 40778 | AB6: 41337 | AC6: =IFERROR(STDEV(Z6:AB6)/AVERAGE(Z6:AB6),0) -> 0.24171751 | AD6: =AVERAGE(I6:O6) -> 18625.714 | AE6: =AVERAGE(Q6:W6) -> 49184.286 | AF6: =AE6/AD6 -> 2.6406657 | AG6: =TTEST(I6:O6,Q6:W6,2,3) -> 0.00094646903 | AH6: =IF(AG6<0.001,"***",IF(AG6<0.01,"**",IF(AG6<0.05,"*","-"))) -> *** | AI6: =_xlfn.RANK.EQ(AG6,$AG$4:$AG$390,1) -> 19 | AJ6: =COUNTIF($AI$4:$AI$390,AI6)+AI6-1 -> 19 | AK6: =MIN(AG6*$AJ$3/AJ6,1) -> 0.01927808 | AL6: =MIN(AK6,IFERROR(VLOOKUP(AJ6+1,$AJ$4:$AL$390,3,FALSE),1)) -> 0.017929651 | AM6: =IF(AL6<0.05,"**",IF(AL6<0.1,"*","")) -> **
A7: Neg | B7: 164 | C7: 329.24811 | D7: 5.18 | E7: -1 | F7: FA(22:5) | G7: FA | I7: 5353 | J7: 6562 | K7: 6401 | L7: 4138 | M7: 5978 | N7: 7871 | O7: 6694 | Q7: 10216 | R7: 23442 | S7: 11433 | T7: 10272 | U7: 14170 | V7: 9754 | W7: 14700 | Y7: 167 | Z7: 9303 | AA7: 8994 | AB7: 12164 | AC7: =IFERROR(STDEV(Z7:AB7)/AVERAGE(Z7:AB7),0) -> 0.17213896 | AD7: =AVERAGE(I7:O7) -> 6142.4286 | AE7: =AVERAGE(Q7:W7) -> 13426.714 | AF7: =AE7/AD7 -> 2.1858967 | AG7: =TTEST(I7:O7,Q7:W7,2,3) -> 0.0066320837 | AH7: =IF(AG7<0.001,"***",IF(AG7<0.01,"**",IF(AG7<0.05,"*","-"))) -> ** | AI7: =_xlfn.RANK.EQ(AG7,$AG$4:$AG$390,1) -> 60 | AJ7: =COUNTIF($AI$4:$AI$390,AI7)+AI7-1 -> 60 | AK7: =MIN(AG7*$AJ$3/AJ7,1) -> 0.04277694 | AL7: =MIN(AK7,IFERROR(VLOOKUP(AJ7+1,$AJ$4:$AL$390,3,FALSE),1)) -> 0.04277694 | AM7: =IF(AL7<0.05,"**",IF(AL7<0.1,"*","")) -> **
A8: Neg | B8: 228 | C8: 303.23016 | D8: 4.974875 | E8: -1 | F8: FA(20:4) | G8: FA | I8: 8490 | J8: 8698 | K8: 7419 | L8: 6295 | M8: 8047 | N8: 11642 | O8: 10660 | Q8: 7594 | R8: 16710 | S8: 9367 | T8: 11211 | U8: 17356 | V8: 12035 | W8: 17447 | Y8: 728 | Z8: 10645 | AA8: 11131 | AB8: 12115 | AC8: =IFERROR(STDEV(Z8:AB8)/AVERAGE(Z8:AB8),0) -> 0.066294347 | AD8: =AVERAGE(I8:O8) -> 8750.1429 | AE8: =AVERAGE(Q8:W8) -> 13102.857 | AF8: =AE8/AD8 -> 1.4974449 | AG8: =TTEST(I8:O8,Q8:W8,2,3) -> 0.031353985 | AH8: =IF(AG8<0.001,"***",IF(AG8<0.01,"**",IF(AG8<0.05,"*","-"))) -> * | AI8: =_xlfn.RANK.EQ(AG8,$AG$4:$AG$390,1) -> 133 | AJ8: =COUNTIF($AI$4:$AI$390,AI8)+AI8-1 -> 133 | AK8: =MIN(AG8*$AJ$3/AJ8,1) -> 0.091233025 | AL8: =MIN(AK8,IFERROR(VLOOKUP(AJ8+1,$AJ$4:$AL$390,3,FALSE),1)) -> 0.091233025 | AM8: =IF(AL8<0.05,"**",IF(AL8<0.1,"*","")) -> *
A9: Neg | B9: 241 | C9: 301.2162 | D9: 4.5628147 | E9: -1 | F9: FA(20:5) | G9: FA | I9: 3719 | J9: 2941 | K9: 4994 | L9: 3191 | M9: 2792 | N9: 4254 | O9: 6167 | Q9: 6393 | R9: 11969 | S9: 6071 | T9: 8059 | U9: 16371 | V9: 4818 | W9: 13482 | Y9: 4 | Z9: 7547 | AA9: 5530 | AB9: 8840 | AC9: =IFERROR(STDEV(Z9:AB9)/AVERAGE(Z9:AB9),0) -> 0.22833571 | AD9: =AVERAGE(I9:O9) -> 4008.2857 | AE9: =AVERAGE(Q9:W9) -> 9594.7143 | AF9: =AE9/AD9 -> 2.3937202 | AG9: =TTEST(I9:O9,Q9:W9,2,3) -> 0.014082499 | AH9: =IF(AG9<0.001,"***",IF(AG9<0.01,"**",IF(AG9<0.05,"*","-"))) -> * | AI9: =_xlfn.RANK.EQ(AG9,$AG$4:$AG$390,1) -> 91 | AJ9: =COUNTIF($AI$4:$AI$390,AI9)+AI9-1 -> 91 | AK9: =MIN(AG9*$AJ$3/AJ9,1) -> 0.059889309 | AL9: =MIN(AK9,IFERROR(VLOOKUP(AJ9+1,$AJ$4:$AL$390,3,FALSE),1)) -> 0.059889309 | AM9: =IF(AL9<0.05,"**",IF(AL9<0.1,"*","")) -> *
A10: Neg | B10: 494 | C10: 253.2171 | D10: 4.7677179 | E10: -2 | F10: FA(16:1) | G10: FA | I10: 2778 | J10: 1996 | K10: 2420 | L10: 2114 | M10: 1655 | N10: 2643 | O10: 2203 | Q10: 7192 | R10: 8832 | S10: 6043 | T10: 5212 | U10: 5960 | V10: 4757 | W10: 6868 | Y10: 1125 | Z10: 3690 | AA10: 3536 | AB10: 5289 | AC10: =IFERROR(STDEV(Z10:AB10)/AVERAGE(Z10:AB10),0) -> 0.23268826 | AD10: =AVERAGE(I10:O10) -> 2258.4286 | AE10: =AVERAGE(Q10:W10) -> 6409.1429 | AF10: =AE10/AD10 -> 2.8378772 | AG10: =TTEST(I10:O10,Q10:W10,2,3) -> 0.00011634331 | AH10: =IF(AG10<0.001,"***",IF(AG10<0.01,"**",IF(AG10<0.05,"*","-"))) -> *** | AI10: =_xlfn.RANK.EQ(AG10,$AG$4:$AG$390,1) -> 7 | AJ10: =COUNTIF($AI$4:$AI$390,AI10)+AI10-1 -> 7 | AK10: =MIN(AG10*$AJ$3/AJ10,1) -> 0.0064321233 | AL10: =MIN(AK10,IFERROR(VLOOKUP(AJ10+1,$AJ$4:$AL$390,3,FALSE),1)) -> 0.0064321233 | AM10: =IF(AL10<0.05,"**",IF(AL10<0.1,"*","")) -> **
A11: Neg | B11: 510 | C11: 277.21699 | D11: 4.5849515 | E11: -1 | F11: FA(18:3) | G11: FA | I11: 1510 | J11: 1281 | K11: 1386 | L11: 804 | M11: 2244 | N11: 2231 | O11: 2593 | Q11: 1755 | R11: 5649 | S11: 3071 | T11: 3390 | U11: 6910 | V11: 2819 | W11: 4620 | Y11: 645 | Z11: 3361 | AA11: 2626 | AB11: 3711 | AC11: =IFERROR(STDEV(Z11:AB11)/AVERAGE(Z11:AB11),0) -> 0.17130359 | AD11: =AVERAGE(I11:O11) -> 1721.2857 | AE11: =AVERAGE(Q11:W11) -> 4030.5714 | AF11: =AE11/AD11 -> 2.3416051 | AG11: =TTEST(I11:O11,Q11:W11,2,3) -> 0.013454027 | AH11: =IF(AG11<0.001,"***",IF(AG11<0.01,"**",IF(AG11<0.05,"*","-"))) -> * | AI11: =_xlfn.RANK.EQ(AG11,$AG$4:$AG$390,1) -> 87 | AJ11: =COUNTIF($AI$4:$AI$390,AI11)+AI11-1 -> 87 | AK11: =MIN(AG11*$AJ$3/AJ11,1) -> 0.059847225 | AL11: =MIN(AK11,IFERROR(VLOOKUP(AJ11+1,$AJ$4:$AL$390,3,FALSE),1)) -> 0.059510362 | AM11: =IF(AL11<0.05,"**",IF(AL11<0.1,"*","")) -> *
A12: Neg | B12: 522 | C12: 309.27895 | D12: 6.0793781 | E12: -1 | F12: FA(20:1) | G12: FA | I12: 5745 | J12: 5270 | K12: 4761 | L12: 2581 | M12: 6290 | N12: 6694 | O12: 5381 | Q12: 2154 | R12: 5811 | S12: 3442 | T12: 2361 | U12: 4598 | V12: 1902 | W12: 3644 | Y12: 184 | Z12: 4062 | AA12: 4080 | AB12: 4790 | AC12: =IFERROR(STDEV(Z12:AB12)/AVERAGE(Z12:AB12),0) -> 0.096322084 | AD12: =AVERAGE(I12:O12) -> 5246 | AE12: =AVERAGE(Q12:W12) -> 3416 | AF12: =AE12/AD12 -> 0.65116279 | AG12: =TTEST(I12:O12,Q12:W12,2,3) -> 0.029330111 | AH12: =IF(AG12<0.001,"***",IF(AG12<0.01,"**",IF(AG12<0.05,"*","-"))) -> * | AI12: =_xlfn.RANK.EQ(AG12,$AG$4:$AG$390,1) -> 127 | AJ12: =COUNTIF($AI$4:$AI$390,AI12)+AI12-1 -> 127 | AK12: =MIN(AG12*$AJ$3/AJ12,1) -> 0.089376008 | AL12: =MIN(AK12,IFERROR(VLOOKUP(AJ12+1,$AJ$4:$AL$390,3,FALSE),1)) -> 0.089376008 | AM12: =IF(AL12<0.05,"**",IF(AL12<0.1,"*","")) -> *
A13: Neg | B13: 1004 | C13: 337.31002 | D13: 6.6161863 | E13: -1 | F13: FA(22:1) | G13: FA | I13: 2129 | J13: 2842 | K13: 3030 | L13: 1094 | M13: 2970 | N13: 3281 | O13: 3023 | Q13: 1036 | R13: 3325 | S13: 2508 | T13: 2211 | U13: 2838 | V13: 1613 | W13: 2607 | Y13: 553 | Z13: 2138 | AA13: 2577 | AB13: 2843 | AC13: =IFERROR(STDEV(Z13:AB13)/AVERAGE(Z13:AB13),0) -> 0.14131521 | AD13: =AVERAGE(I13:O13) -> 2624.1429 | AE13: =AVERAGE(Q13:W13) -> 2305.4286 | AF13: =AE13/AD13 -> 0.87854538 | AG13: =TTEST(I13:O13,Q13:W13,2,3) -> 0.45211783 | AH13: =IF(AG13<0.001,"***",IF(AG13<0.01,"**",IF(AG13<0.05,"*","-"))) -> - | AI13: =_xlfn.RANK.EQ(AG13,$AG$4:$AG$390,1) -> 309 | AJ13: =COUNTIF($AI$4:$AI$390,AI13)+AI13-1 -> 309 | AK13: =MIN(AG13*$AJ$3/AJ13,1) -> 0.56624467 | AL13: =MIN(AK13,IFERROR(VLOOKUP(AJ13+1,$AJ$4:$AL$390,3,FALSE),1)) -> 0.56624467 | AM13: =IF(AL13<0.05,"**",IF(AL13<0.1,"*",""))
A14: Neg | B14: 1216 | C14: 275.20125 | D14: 4.1953231 | E14: -1 | F14: FA(18:4) | G14: FA | I14: 386 | J14: 297 | K14: 358 | L14: 484 | M14: 373 | N14: 255 | O14: 184 | Q14: 242 | R14: 1039 | S14: 519 | T14: 799 | U14: 2697 | V14: 631 | W14: 1265 | Y14: 9 | Z14: 512 | AA14: 775 | AB14: 819 | AC14: =IFERROR(STDEV(Z14:AB14)/AVERAGE(Z14:AB14),0) -> 0.23648011 | AD14: =AVERAGE(I14:O14) -> 333.85714 | AE14: =AVERAGE(Q14:W14) -> 1027.4286 | AF14: =AE14/AD14 -> 3.0774497 | AG14: =TTEST(I14:O14,Q14:W14,2,3) -> 0.064077301 | AH14: =IF(AG14<0.001,"***",IF(AG14<0.01,"**",IF(AG14<0.05,"*","-"))) -> - | AI14: =_xlfn.RANK.EQ(AG14,$AG$4:$AG$390,1) -> 174 | AJ14: =COUNTIF($AI$4:$AI$390,AI14)+AI14-1 -> 174 | AK14: =MIN(AG14*$AJ$3/AJ14,1) -> 0.14251676 | AL14: =MIN(AK14,IFERROR(VLOOKUP(AJ14+1,$AJ$4:$AL$390,3,FALSE),1)) -> 0.14201734 | AM14: =IF(AL14<0.05,"**",IF(AL14<0.1,"*",""))
A15: Neg | B15: 1612 | C15: 307.26297 | D15: 5.66105 | E15: -1 | F15: FA(20:2) | G15: FA | I15: 781 | J15: 924 | K15: 683 | L15: 145 | M15: 764 | N15: 1296 | O15: 911 | Q15: 1006 | R15: 1965 | S15: 1484 | T15: 936 | U15: 1261 | V15: 1056 | W15: 1877 | Y15: 42 | Z15: 1155 | AA15: 1182 | AB15: 1361 | AC15: =IFERROR(STDEV(Z15:AB15)/AVERAGE(Z15:AB15),0) -> 0.090824908 | AD15: =AVERAGE(I15:O15) -> 786.28571 | AE15: =AVERAGE(Q15:W15) -> 1369.2857 | AF15: =AE15/AD15 -> 1.7414608 | AG15: =TTEST(I15:O15,Q15:W15,2,3) -> 0.015419535 | AH15: =IF(AG15<0.001,"***",IF(AG15<0.01,"**",IF(AG15<0.05,"*","-"))) -> * | AI15: =_xlfn.RANK.EQ(AG15,$AG$4:$AG$390,1) -> 96 | AJ15: =COUNTIF($AI$4:$AI$390,AI15)+AI15-1 -> 96 | AK15: =MIN(AG15*$AJ$3/AJ15,1) -> 0.062159999 | AL15: =MIN(AK15,IFERROR(VLOOKUP(AJ15+1,$AJ$4:$AL$390,3,FALSE),1)) -> 0.061455853 | AM15: =IF(AL15<0.05,"**",IF(AL15<0.1,"*","")) -> *
... A286: Neg | B286: 2072 | C286: 949.5187 | D286: 6.5842784 | E286: -1 | F286: GPPG(18:2/20:3) | G286: GPPG | I286: 637 | J286: 1060 | K286: 818 | L286: 756 | M286: 1071 | N286: 1094 | O286: 1470 | Q286: 657 | R286: 500 | S286: 1173 | T286: 1151 | U286: 1077 | V286: 953 | W286: 1193 | Y286: 0 | Z286: 1007 | AA286: 938 | AB286: 800 | AC286: =IFERROR(STDEV(Z286:AB286)/AVERAGE(Z286:AB286),0) -> 0.11519043 | AD286: =AVERAGE(I286:O286) -> 986.57143 | AE286: =AVERAGE(Q286:W286) -> 957.71429 | AF286: =AE286/AD286 -> 0.97075007 | AG286: =TTEST(I286:O286,Q286:W286,2,3) -> 0.84824901 | AH286: =IF(AG286<0.001,"***",IF(AG286<0.01,"**",IF(AG286<0.05,"*","-"))) -> - | AI286: =_xlfn.RANK.EQ(AG286,$AG$4:$AG$390,1) -> 371 | AJ286: =COUNTIF($AI$4:$AI$390,AI286)+AI286-1 -> 371 | AK286: =MIN(AG286*$AJ$3/AJ286,1) -> 0.88483117 | AL286: =MIN(AK286,IFERROR(VLOOKUP(AJ286+1,$AJ$4:$AL$390,3,FALSE),1)) -> 0.88483117 | AM286: =IF(AL286<0.05,"**",IF(AL286<0.1,"*",""))
A287: Neg | B287: 2334 | C287: 901.5154 | D287: 6.839209 | E287: -1 | F287: GPPG(16:0/18:1) | G287: GPPG | H287: 薄くて定性難。前回定性から推定。 | I287: 709 | J287: 578 | K287: 695 | L287: 709 | M287: 675 | N287: 1300 | O287: 588 | Q287: 507 | R287: 361 | S287: 302 | T287: 412 | U287: 509 | V287: 200 | W287: 667 | Y287: 0 | Z287: 645 | AA287: 595 | AB287: 829 | AC287: =IFERROR(STDEV(Z287:AB287)/AVERAGE(Z287:AB287),0) -> 0.17867876 | AD287: =AVERAGE(I287:O287) -> 750.57143 | AE287: =AVERAGE(Q287:W287) -> 422.57143 | AF287: =AE287/AD287 -> 0.56299962 | AG287: =TTEST(I287:O287,Q287:W287,2,3) -> 0.014047672 | AH287: =IF(AG287<0.001,"***",IF(AG287<0.01,"**",IF(AG287<0.05,"*","-"))) -> * | AI287: =_xlfn.RANK.EQ(AG287,$AG$4:$AG$390,1) -> 90 | AJ287: =COUNTIF($AI$4:$AI$390,AI287)+AI287-1 -> 90 | AK287: =MIN(AG287*$AJ$3/AJ287,1) -> 0.06040499 | AL287: =MIN(AK287,IFERROR(VLOOKUP(AJ287+1,$AJ$4:$AL$390,3,FALSE),1)) -> 0.059889309 | AM287: =IF(AL287<0.05,"**",IF(AL287<0.1,"*","")) -> *
A288: Neg | B288: 717 | C288: 923.50422 | D288: 6.1248167 | E288: -1 | F288: DLCL(18:2/18:2) | G288: DLCL | I288: 2723 | J288: 2189 | K288: 1460 | L288: 2662 | M288: 2485 | N288: 3347 | O288: 2046 | Q288: 4835 | R288: 185 | S288: 1133 | T288: 2918 | U288: 2497 | V288: 5285 | W288: 2120 | Y288: 0 | Z288: 2598 | AA288: 2500 | AB288: 2613 | AC288: =IFERROR(STDEV(Z288:AB288)/AVERAGE(Z288:AB288),0) -> 0.02387646 | AD288: =AVERAGE(I288:O288) -> 2416 | AE288: =AVERAGE(Q288:W288) -> 2710.4286 | AF288: =AE288/AD288 -> 1.1218661 | AG288: =TTEST(I288:O288,Q288:W288,2,3) -> 0.69957262 | AH288: =IF(AG288<0.001,"***",IF(AG288<0.01,"**",IF(AG288<0.05,"*","-"))) -> - | AI288: =_xlfn.RANK.EQ(AG288,$AG$4:$AG$390,1) -> 349 | AJ288: =COUNTIF($AI$4:$AI$390,AI288)+AI288-1 -> 349 | AK288: =MIN(AG288*$AJ$3/AJ288,1) -> 0.77574385 | AL288: =MIN(AK288,IFERROR(VLOOKUP(AJ288+1,$AJ$4:$AL$390,3,FALSE),1)) -> 0.77574385 | AM288: =IF(AL288<0.05,"**",IF(AL288<0.1,"*",""))
A289: Neg | B289: 812 | C289: 925.51991 | D289: 6.29155 | E289: -1 | F289: DLCL(18:1/18:2) | G289: DLCL | I289: 1098 | J289: 852 | K289: 646 | L289: 569 | M289: 551 | N289: 1494 | O289: 643 | Q289: 2730 | R289: 376 | S289: 947 | T289: 1671 | U289: 1179 | V289: 4236 | W289: 1561 | Y289: 0 | Z289: 940 | AA289: 1516 | AB289: 1411 | AC289: =IFERROR(STDEV(Z289:AB289)/AVERAGE(Z289:AB289),0) -> 0.23798964 | AD289: =AVERAGE(I289:O289) -> 836.14286 | AE289: =AVERAGE(Q289:W289) -> 1814.2857 | AF289: =AE289/AD289 -> 2.1698274 | AG289: =TTEST(I289:O289,Q289:W289,2,3) -> 0.095124546 | AH289: =IF(AG289<0.001,"***",IF(AG289<0.01,"**",IF(AG289<0.05,"*","-"))) -> - | AI289: =_xlfn.RANK.EQ(AG289,$AG$4:$AG$390,1) -> 189 | AJ289: =COUNTIF($AI$4:$AI$390,AI289)+AI289-1 -> 189 | AK289: =MIN(AG289*$AJ$3/AJ289,1) -> 0.19477883 | AL289: =MIN(AK289,IFERROR(VLOOKUP(AJ289+1,$AJ$4:$AL$390,3,FALSE),1)) -> 0.19477883 | AM289: =IF(AL289<0.05,"**",IF(AL289<0.1,"*",""))
A290: Neg | B290: 1841 | C290: 927.53704 | D290: 6.5051208 | E290: -1 | F290: DLCL(18:1/18:1) | G290: DLCL | I290: 61 | J290: 186 | K290: 64 | L290: 126 | M290: 97 | N290: 322 | O290: 81 | Q290: 734 | R290: 232 | S290: 350 | T290: 662 | U290: 570 | V290: 1679 | W290: 481 | Y290: 0 | Z290: 330 | AA290: 318 | AB290: 403 | AC290: =IFERROR(STDEV(Z290:AB290)/AVERAGE(Z290:AB290),0) -> 0.13131386 | AD290: =AVERAGE(I290:O290) -> 133.85714 | AE290: =AVERAGE(Q290:W290) -> 672.57143 | AF290: =AE290/AD290 -> 5.0245464 | AG290: =TTEST(I290:O290,Q290:W290,2,3) -> 0.02394961 | AH290: =IF(AG290<0.001,"***",IF(AG290<0.01,"**",IF(AG290<0.05,"*","-"))) -> * | AI290: =_xlfn.RANK.EQ(AG290,$AG$4:$AG$390,1) -> 119 | AJ290: =COUNTIF($AI$4:$AI$390,AI290)+AI290-1 -> 119 | AK290: =MIN(AG290*$AJ$3/AJ290,1) -> 0.077886545 | AL290: =MIN(AK290,IFERROR(VLOOKUP(AJ290+1,$AJ$4:$AL$390,3,FALSE),1)) -> 0.077886545 | AM290: =IF(AL290<0.05,"**",IF(AL290<0.1,"*","")) -> *
A291: Neg | B291: 2470 | C291: 973.52431 | D291: 6.2591409 | E291: -1 | F291: DLCL(18:1/22:6) | G291: DLCL | H291: MS/MSなし。前回定性から推定。 | I291: 195 | J291: 266 | K291: 96 | L291: 133 | M291: 42 | N291: 324 | O291: 108 | Q291: 1060 | R291: 121 | S291: 651 | T291: 548 | U291: 625 | V291: 1224 | W291: 471 | Y291: 60 | Z291: 396 | AA291: 264 | AB291: 278 | AC291: =IFERROR(STDEV(Z291:AB291)/AVERAGE(Z291:AB291),0) -> 0.23190023 | AD291: =AVERAGE(I291:O291) -> 166.28571 | AE291: =AVERAGE(Q291:W291) -> 671.42857 | AF291: =AE291/AD291 -> 4.0378007 | AG291: =TTEST(I291:O291,Q291:W291,2,3) -> 0.010345953 | AH291: =IF(AG291<0.001,"***",IF(AG291<0.01,"**",IF(AG291<0.05,"*","-"))) -> * | AI291: =_xlfn.RANK.EQ(AG291,$AG$4:$AG$390,1) -> 75 | AJ291: =COUNTIF($AI$4:$AI$390,AI291)+AI291-1 -> 75 | AK291: =MIN(AG291*$AJ$3/AJ291,1) -> 0.053385117 | AL291: =MIN(AK291,IFERROR(VLOOKUP(AJ291+1,$AJ$4:$AL$390,3,FALSE),1)) -> 0.053385117 | AM291: =IF(AL291<0.05,"**",IF(AL291<0.1,"*","")) -> *
A292: Neg | B292: 964 | C292: 827.48363 | D292: 6.978341 | E292: -2 | F292: PGP(16:0/18:1) | G292: PGP | I292: 1309 | J292: 1164 | K292: 1159 | L292: 839 | M292: 1444 | N292: 2355 | O292: 1693 | Q292: 2214 | R292: 3466 | S292: 1617 | T292: 2092 | U292: 3448 | V292: 2570 | W292: 3138 | Y292: 486 | Z292: 1638 | AA292: 1940 | AB292: 2112 | AC292: =IFERROR(STDEV(Z292:AB292)/AVERAGE(Z292:AB292),0) -> 0.12651289 | AD292: =AVERAGE(I292:O292) -> 1423.2857 | AE292: =AVERAGE(Q292:W292) -> 2649.2857 | AF292: =AE292/AD292 -> 1.8613871 | AG292: =TTEST(I292:O292,Q292:W292,2,3) -> 0.00359223 | AH292: =IF(AG292<0.001,"***",IF(AG292<0.01,"**",IF(AG292<0.05,"*","-"))) -> ** | AI292: =_xlfn.RANK.EQ(AG292,$AG$4:$AG$390,1) -> 43 | AJ292: =COUNTIF($AI$4:$AI$390,AI292)+AI292-1 -> 43 | AK292: =MIN(AG292*$AJ$3/AJ292,1) -> 0.03233007 | AL292: =MIN(AK292,IFERROR(VLOOKUP(AJ292+1,$AJ$4:$AL$390,3,FALSE),1)) -> 0.03233007 | AM292: =IF(AL292<0.05,"**",IF(AL292<0.1,"*","")) -> **
A293: Neg | B293: 2287 | C293: 825.46674 | D293: 6.7474958 | E293: -1 | F293: PGP(16:0/18:2) | G293: PGP | I293: 633 | J293: 187 | K293: 572 | L293: 480 | M293: 673 | N293: 1028 | O293: 781 | Q293: 555 | R293: 868 | S293: 554 | T293: 147 | U293: 1009 | V293: 801 | W293: 1326 | Y293: 14 | Z293: 669 | AA293: 723 | AB293: 814 | AC293: =IFERROR(STDEV(Z293:AB293)/AVERAGE(Z293:AB293),0) -> 0.099658964 | AD293: =AVERAGE(I293:O293) -> 622 | AE293: =AVERAGE(Q293:W293) -> 751.42857 | AF293: =AE293/AD293 -> 1.2080845 | AG293: =TTEST(I293:O293,Q293:W293,2,3) -> 0.47112677 | AH293: =IF(AG293<0.001,"***",IF(AG293<0.01,"**",IF(AG293<0.05,"*","-"))) -> - | AI293: =_xlfn.RANK.EQ(AG293,$AG$4:$AG$390,1) -> 313 | AJ293: =COUNTIF($AI$4:$AI$390,AI293)+AI293-1 -> 313 | AK293: =MIN(AG293*$AJ$3/AJ293,1) -> 0.58251138 | AL293: =MIN(AK293,IFERROR(VLOOKUP(AJ293+1,$AJ$4:$AL$390,3,FALSE),1)) -> 0.58251138 | AM293: =IF(AL293<0.05,"**",IF(AL293<0.1,"*",""))
A294: Neg | B294: 1775 | C294: 1009.7465 | D294: 10.743074 | E294: -1 | F294: HBMP(16:0/18:1/g18:2) | G294: HBMP | I294: 609 | J294: 539 | K294: 1097 | L294: 918 | M294: 915 | N294: 903 | O294: 937 | Q294: 945 | R294: 884 | S294: 597 | T294: 1393 | U294: 1287 | V294: 981 | W294: 1750 | Y294: 0 | Z294: 990 | AA294: 920 | AB294: 1006 | AC294: =IFERROR(STDEV(Z294:AB294)/AVERAGE(Z294:AB294),0) -> 0.047055953 | AD294: =AVERAGE(I294:O294) -> 845.42857 | AE294: =AVERAGE(Q294:W294) -> 1119.5714 | AF294: =AE294/AD294 -> 1.324265 | AG294: =TTEST(I294:O294,Q294:W294,2,3) -> 0.12653682 | AH294: =IF(AG294<0.001,"***",IF(AG294<0.01,"**",IF(AG294<0.05,"*","-"))) -> - | AI294: =_xlfn.RANK.EQ(AG294,$AG$4:$AG$390,1) -> 212 | AJ294: =COUNTIF($AI$4:$AI$390,AI294)+AI294-1 -> 212 | AK294: =MIN(AG294*$AJ$3/AJ294,1) -> 0.23098938 | AL294: =MIN(AK294,IFERROR(VLOOKUP(AJ294+1,$AJ$4:$AL$390,3,FALSE),1)) -> 0.23098938 | AM294: =IF(AL294<0.05,"**",IF(AL294<0.1,"*",""))
A295: Neg | B295: 5699 | C295: 1057.7454 | D295: 10.617549 | E295: -1 | F295: HBMP(16:0/18:1/g22:6) | G295: HBMP | I295: 194 | J295: 177 | K295: 421 | L295: 191 | M295: 175 | N295: 288 | O295: 254 | Q295: 313 | R295: 183 | S295: 252 | T295: 402 | U295: 557 | V295: 517 | W295: 602 | Y295: 0 | Z295: 298 | AA295: 373 | AB295: 480 | AC295: =IFERROR(STDEV(Z295:AB295)/AVERAGE(Z295:AB295),0) -> 0.23840399 | AD295: =AVERAGE(I295:O295) -> 242.85714 | AE295: =AVERAGE(Q295:W295) -> 403.71429 | AF295: =AE295/AD295 -> 1.6623529 | AG295: =TTEST(I295:O295,Q295:W295,2,3) -> 0.045084244 | AH295: =IF(AG295<0.001,"***",IF(AG295<0.01,"**",IF(AG295<0.05,"*","-"))) -> * | AI295: =_xlfn.RANK.EQ(AG295,$AG$4:$AG$390,1) -> 157 | AJ295: =COUNTIF($AI$4:$AI$390,AI295)+AI295-1 -> 157 | AK295: =MIN(AG295*$AJ$3/AJ295,1) -> 0.11113123 | AL295: =MIN(AK295,IFERROR(VLOOKUP(AJ295+1,$AJ$4:$AL$390,3,FALSE),1)) -> 0.11113123 | AM295: =IF(AL295<0.05,"**",IF(AL295<0.1,"*",""))
A296: Neg | B296: 426 | C296: 1185.7363 | D296: 8.3487451 | E296: -1 | F296: MLCL(18:2/18:2/18:2) | G296: MLCL | I296: 5338 | J296: 6469 | K296: 5527 | L296: 6346 | M296: 6466 | N296: 6862 | O296: 8549 | Q296: 3249 | R296: 5908 | S296: 4384 | T296: 4336 | U296: 3290 | V296: 4081 | W296: 3390 | Y296: 0 | Z296: 4899 | AA296: 6099 | AB296: 7003 | AC296: =IFERROR(STDEV(Z296:AB296)/AVERAGE(Z296:AB296),0) -> 0.17590098 | AD296: =AVERAGE(I296:O296) -> 6508.1429 | AE296: =AVERAGE(Q296:W296) -> 4091.1429 | AF296: =AE296/AD296 -> 0.62861909 | AG296: =TTEST(I296:O296,Q296:W296,2,3) -> 0.00070878843 | AH296: =IF(AG296<0.001,"***",IF(AG296<0.01,"**",IF(AG296<0.05,"*","-"))) -> *** | AI296: =_xlfn.RANK.EQ(AG296,$AG$4:$AG$390,1) -> 17 | AJ296: =COUNTIF($AI$4:$AI$390,AI296)+AI296-1 -> 17 | AK296: =MIN(AG296*$AJ$3/AJ296,1) -> 0.01613536 | AL296: =MIN(AK296,IFERROR(VLOOKUP(AJ296+1,$AJ$4:$AL$390,3,FALSE),1)) -> 0.015540483 | AM296: =IF(AL296<0.05,"**",IF(AL296<0.1,"*","")) -> **
A297: Neg | B297: 702 | C297: 1233.7365 | D297: 8.2990531 | E297: -1 | F297: MLCL(18:2/18:2/22:6) | G297: MLCL | I297: 2679 | J297: 3583 | K297: 2199 | L297: 2095 | M297: 2351 | N297: 4344 | O297: 5002 | Q297: 3185 | R297: 2688 | S297: 3105 | T297: 2893 | U297: 2101 | V297: 3575 | W297: 3476 | Y297: 0 | Z297: 2960 | AA297: 4086 | AB297: 3920 | AC297: =IFERROR(STDEV(Z297:AB297)/AVERAGE(Z297:AB297),0) -> 0.1662966 | AD297: =AVERAGE(I297:O297) -> 3179 | AE297: =AVERAGE(Q297:W297) -> 3003.2857 | AF297: =AE297/AD297 -> 0.94472655 | AG297: =TTEST(I297:O297,Q297:W297,2,3) -> 0.72019554 | AH297: =IF(AG297<0.001,"***",IF(AG297<0.01,"**",IF(AG297<0.05,"*","-"))) -> - | AI297: =_xlfn.RANK.EQ(AG297,$AG$4:$AG$390,1) -> 351 | AJ297: =COUNTIF($AI$4:$AI$390,AI297)+AI297-1 -> 351 | AK297: =MIN(AG297*$AJ$3/AJ297,1) -> 0.79406175 | AL297: =MIN(AK297,IFERROR(VLOOKUP(AJ297+1,$AJ$4:$AL$390,3,FALSE),1)) -> 0.79345972 | AM297: =IF(AL297<0.05,"**",IF(AL297<0.1,"*",""))
A298: Neg | B298: 705 | C298: 1187.7495 | D298: 8.7329098 | E298: -1 | F298: MLCL(18:1/18:2/18:2) | G298: MLCL | I298: 2437 | J298: 2047 | K298: 2802 | L298: 1870 | M298: 2694 | N298: 3298 | O298: 2739 | Q298: 3096 | R298: 2404 | S298: 3472 | T298: 2593 | U298: 3316 | V298: 4956 | W298: 2644 | Y298: 0 | Z298: 3046 | AA298: 2701 | AB298: 3445 | AC298: =IFERROR(STDEV(Z298:AB298)/AVERAGE(Z298:AB298),0) -> 0.12151647 | AD298: =AVERAGE(I298:O298) -> 2555.2857 | AE298: =AVERAGE(Q298:W298) -> 3211.5714 | AF298: =AE298/AD298 -> 1.2568346 | AG298: =TTEST(I298:O298,Q298:W298,2,3) -> 0.11233663 | AH298: =IF(AG298<0.001,"***",IF(AG298<0.01,"**",IF(AG298<0.05,"*","-"))) -> - | AI298: =_xlfn.RANK.EQ(AG298,$AG$4:$AG$390,1) -> 203 | AJ298: =COUNTIF($AI$4:$AI$390,AI298)+AI298-1 -> 203 | AK298: =MIN(AG298*$AJ$3/AJ298,1) -> 0.21415899 | AL298: =MIN(AK298,IFERROR(VLOOKUP(AJ298+1,$AJ$4:$AL$390,3,FALSE),1)) -> 0.21415899 | AM298: =IF(AL298<0.05,"**",IF(AL298<0.1,"*",""))
A299: Neg | B299: 22 | C299: 1447.967 | D299: 12.275452 | E299: -1 | F299: CL(18:2/18:2/18:2/18:2) | G299: CL | I299: 211919 | J299: 179761 | K299: 246291 | L299: 252751 | M299: 315433 | N299: 257594 | O299: 333033 | Q299: 143916 | R299: 180283 | S299: 115793 | T299: 240544 | U299: 197036 | V299: 150568 | W299: 201985 | Y299: 0 | Z299: 205946 | AA299: 234103 | AB299: 233652 | AC299: =IFERROR(STDEV(Z299:AB299)/AVERAGE(Z299:AB299),0) -> 0.071817478 | AD299: =AVERAGE(I299:O299) -> 256683.14 | AE299: =AVERAGE(Q299:W299) -> 175732.14 | AF299: =AE299/AD299 -> 0.68462674 | AG299: =TTEST(I299:O299,Q299:W299,2,3) -> 0.0090989349 | AH299: =IF(AG299<0.001,"***",IF(AG299<0.01,"**",IF(AG299<0.05,"*","-"))) -> ** | AI299: =_xlfn.RANK.EQ(AG299,$AG$4:$AG$390,1) -> 71 | AJ299: =COUNTIF($AI$4:$AI$390,AI299)+AI299-1 -> 71 | AK299: =MIN(AG299*$AJ$3/AJ299,1) -> 0.049595603 | AL299: =MIN(AK299,IFERROR(VLOOKUP(AJ299+1,$AJ$4:$AL$390,3,FALSE),1)) -> 0.049278317 | AM299: =IF(AL299<0.05,"**",IF(AL299<0.1,"*","")) -> **
A300: Neg | B300: 39 | C300: 1495.9676 | D300: 12.157075 | E300: -1 | F300: CL(18:2/18:2/18:2/22:6) | G300: CL | I300: 94659 | J300: 88016 | K300: 141310 | L300: 105902 | M300: 138936 | N300: 135853 | O300: 166673 | Q300: 86342 | R300: 102071 | S300: 82098 | T300: 126567 | U300: 133532 | V300: 107542 | W300: 140802 | Y300: 0 | Z300: 116009 | AA300: 140881 | AB300: 128135 | AC300: =IFERROR(STDEV(Z300:AB300)/AVERAGE(Z300:AB300),0) -> 0.096907639 | AD300: =AVERAGE(I300:O300) -> 124478.43 | AE300: =AVERAGE(Q300:W300) -> 111279.14 | AF300: =AE300/AD300 -> 0.89396327 | AG300: =TTEST(I300:O300,Q300:W300,2,3) -> 0.36261858 | AH300: =IF(AG300<0.001,"***",IF(AG300<0.01,"**",IF(AG300<0.05,"*","-"))) -> - | AI300: =_xlfn.RANK.EQ(AG300,$AG$4:$AG$390,1) -> 284 | AJ300: =COUNTIF($AI$4:$AI$390,AI300)+AI300-1 -> 284 | AK300: =MIN(AG300*$AJ$3/AJ300,1) -> 0.49413165 | AL300: =MIN(AK300,IFERROR(VLOOKUP(AJ300+1,$AJ$4:$AL$390,3,FALSE),1)) -> 0.49413165 | AM300: =IF(AL300<0.05,"**",IF(AL300<0.1,"*",""))
A301: Neg | B301: 44 | C301: 1449.9816 | D301: 12.771139 | E301: -1 | F301: CL(18:1/18:2/18:2/18:2) | G301: CL | I301: 69859 | J301: 66024 | K301: 102704 | L301: 92168 | M301: 105534 | N301: 108110 | O301: 125186 | Q301: 95223 | R301: 99086 | S301: 59071 | T301: 124244 | U301: 131339 | V301: 107806 | W301: 143632 | Y301: 0 | Z301: 99091 | AA301: 111211 | AB301: 126608 | AC301: =IFERROR(STDEV(Z301:AB301)/AVERAGE(Z301:AB301),0) -> 0.12280119 | AD301: =AVERAGE(I301:O301) -> 95655 | AE301: =AVERAGE(Q301:W301) -> 108628.71 | AF301: =AE301/AD301 -> 1.1356303 | AG301: =TTEST(I301:O301,Q301:W301,2,3) -> 0.3503207 | AH301: =IF(AG301<0.001,"***",IF(AG301<0.01,"**",IF(AG301<0.05,"*","-"))) -> - | AI301: =_xlfn.RANK.EQ(AG301,$AG$4:$AG$390,1) -> 280 | AJ301: =COUNTIF($AI$4:$AI$390,AI301)+AI301-1 -> 280 | AK301: =MIN(AG301*$AJ$3/AJ301,1) -> 0.48419325 | AL301: =MIN(AK301,IFERROR(VLOOKUP(AJ301+1,$AJ$4:$AL$390,3,FALSE),1)) -> 0.48277935 | AM301: =IF(AL301<0.05,"**",IF(AL301<0.1,"*",""))
A302: Neg | B302: 75 | C302: 1497.9807 | D302: 12.653596 | E302: -1 | F302: CL(18:1/18:2/18:2/22:6) | G302: CL | I302: 20154 | J302: 24054 | K302: 39602 | L302: 24469 | M302: 29677 | N302: 39418 | O302: 44083 | Q302: 32693 | R302: 34465 | S302: 30052 | T302: 41080 | U302: 53926 | V302: 44426 | W302: 63221 | Y302: 0 | Z302: 33229 | AA302: 41447 | AB302: 42983 | AC302: =IFERROR(STDEV(Z302:AB302)/AVERAGE(Z302:AB302),0) -> 0.13372387 | AD302: =AVERAGE(I302:O302) -> 31636.714 | AE302: =AVERAGE(Q302:W302) -> 42837.571 | AF302: =AE302/AD302 -> 1.3540462 | AG302: =TTEST(I302:O302,Q302:W302,2,3) -> 0.078170739 | AH302: =IF(AG302<0.001,"***",IF(AG302<0.01,"**",IF(AG302<0.05,"*","-"))) -> - | AI302: =_xlfn.RANK.EQ(AG302,$AG$4:$AG$390,1) -> 184 | AJ302: =COUNTIF($AI$4:$AI$390,AI302)+AI302-1 -> 184 | AK302: =MIN(AG302*$AJ$3/AJ302,1) -> 0.16441346 | AL302: =MIN(AK302,IFERROR(VLOOKUP(AJ302+1,$AJ$4:$AL$390,3,FALSE),1)) -> 0.16441346 | AM302: =IF(AL302<0.05,"**",IF(AL302<0.1,"*",""))
A303: Neg | B303: 93 | C303: 1451.9981 | D303: 13.252983 | E303: -1 | F303: CL(18:1/18:1/18:2/18:2) | G303: CL | I303: 12247 | J303: 14420 | K303: 22600 | L303: 17335 | M303: 22823 | N303: 21508 | O303: 24217 | Q303: 27656 | R303: 27044 | S303: 18335 | T303: 36501 | U303: 47639 | V303: 33900 | W303: 47875 | Y303: 0 | Z303: 25265 | AA303: 31690 | AB303: 32535 | AC303: =IFERROR(STDEV(Z303:AB303)/AVERAGE(Z303:AB303),0) -> 0.13328589 | AD303: =AVERAGE(I303:O303) -> 19307.143 | AE303: =AVERAGE(Q303:W303) -> 34135.714 | AF303: =AE303/AD303 -> 1.7680355 | AG303: =TTEST(I303:O303,Q303:W303,2,3) -> 0.010688293 | AH303: =IF(AG303<0.001,"***",IF(AG303<0.01,"**",IF(AG303<0.05,"*","-"))) -> * | AI303: =_xlfn.RANK.EQ(AG303,$AG$4:$AG$390,1) -> 76 | AJ303: =COUNTIF($AI$4:$AI$390,AI303)+AI303-1 -> 76 | AK303: =MIN(AG303*$AJ$3/AJ303,1) -> 0.054425914 | AL303: =MIN(AK303,IFERROR(VLOOKUP(AJ303+1,$AJ$4:$AL$390,3,FALSE),1)) -> 0.053985977 | AM303: =IF(AL303<0.05,"**",IF(AL303<0.1,"*","")) -> *
... A390: Neg | B390: 113 | C390: 811.61947 | D390: 7.9504539 | E390: -1 | F390: IS(PC_sn2d7)(15:0/18:1) | G390: IS | I390: 11531 | J390: 13684 | K390: 11724 | L390: 14616 | M390: 16617 | N390: 13908 | O390: 15549 | Q390: 13566 | R390: 12128 | S390: 11753 | T390: 17572 | U390: 11996 | V390: 10601 | W390: 14737 | Y390: 38532 | Z390: 15812 | AA390: 10036 | AB390: 14504 | AC390: =IFERROR(STDEV(Z390:AB390)/AVERAGE(Z390:AB390),0) -> 0.22516674 | AD390: =AVERAGE(I390:O390) -> 13947 | AE390: =AVERAGE(Q390:W390) -> 13193.286 | AF390: =AE390/AD390 -> 0.94595868 | AG390: =TTEST(I390:O390,Q390:W390,2,3) -> 0.51960949 | AH390: =IF(AG390<0.001,"***",IF(AG390<0.01,"**",IF(AG390<0.05,"*","-"))) -> - | AI390: =_xlfn.RANK.EQ(AG390,$AG$4:$AG$390,1) -> 328 | AJ390: =COUNTIF($AI$4:$AI$390,AI390)+AI390-1 -> 328 | AK390: =MIN(AG390*$AJ$3/AJ390,1) -> 0.61307583 | AL390: =MIN(AK390,IFERROR(VLOOKUP(AJ390+1,$AJ$4:$AL$390,3,FALSE),1)) -> 0.61307583 | AM390: =IF(AL390<0.05,"**",IF(AL390<0.1,"*",""))
F392: Detection criteria: | AG392: Welch-T Significance | AL392: FDR Significance
F393: height > blank | AG393: P<0.001 : *** | AL393: Q<0.05 : **
F394: height > 100 cps | AG394: P<0.010 : ** | AL394: Q<0.10 : *
F395: RSD in QC samples<25% | AG395: P<0.050 : *

Sheet Molecules_Positive ion mode
F1: 群検出率 | G1: 0.8 | U1: =(AD1-1)/(AD1+1) -> -1 | V1: =(#REF!-1)/(#REF!+1) -> #REF! | W1: =(AH1-1)/(AH1+1) -> -1 | AN1: Control | AV1: HFpEF | BD1: B
I2: Control | J2: Control | K2: Control | L2: Control | M2: Control | N2: Control | O2: Control | Q2: HFpEF | R2: HFpEF | S2: HFpEF | T2: HFpEF | U2: HFpEF | V2: HFpEF | W2: HFpEF | Y2: Blank | Z2: QC | AA2: QC | AB2: QC | AC2: QC | AD2: Mean | AG2: Welch-T | AK2: 平滑化前 | AL2: FDR | AN2: 1 | AO2: 2 | AP2: 3 | AQ2: 4 | AR2: 5 | AS2: 6 | AT2: 7 | AV2: 8 | AW2: 9 | AX2: 1 | AY2: 1 | AZ2: 1 | BA2: 1 | BB2: 1 | BD2: l
A3: Polarity | B3: index | C3: m/z | D3: rt | E3: z | F3: Annotation | G3: Class | H3: コメント | I3: 1 | J3: 2 | K3: 3 | L3: 4 | M3: 5 | N3: 6 | O3: 7 | Q3: 8 | R3: 9 | S3: 10 | T3: 11 | U3: 12 | V3: 13 | W3: 14 | Y3: Blank | Z3: 4 | AA3: 5 | AB3: 6 | AC3: RSD | AD3: Control | AE3: HFpEF | AF3: Fold change | AG3: P-value | AH3: Significance | AI3: 検定数 | AJ3: =COUNT(AJ4:AJ212) -> 209 | AK3: Q値 | AL3: Q-value | AM3: Significance | AX3: 0 | AY3: 1 | AZ3: 2 | BA3: 3 | BB3: 4 | BD3: k
A4: Pos | B4: 30 | C4: 400.34144 | D4: 4.8671245 | E4: 1 | F4: Car(16:0) | G4: Car | I4: 134176 | J4: 127922 | K4: 245857 | L4: 192937 | M4: 137040 | N4: 178891 | O4: 86187 | Q4: 10122 | R4: 30766 | S4: 13512 | T4: 14913 | U4: 27363 | V4: 26402 | W4: 24386 | Y4: 204 | Z4: 99865 | AA4: 84875 | AB4: 85295 | AC4: =IFERROR(STDEV(Z4:AB4)/AVERAGE(Z4:AB4),0) -> 0.094830158 | AD4: =AVERAGE(I4:O4) -> 157572.86 | AE4: =AVERAGE(Q4:W4) -> 21066.286 | AF4: =AE4/AD4 -> 0.13369235 | AG4: =TTEST(I4:O4,Q4:W4,2,3) -> 0.00040047112 | AH4: =IF(AG4<0.001,"***",IF(AG4<0.01,"**",IF(AG4<0.05,"*","-"))) -> *** | AI4: =_xlfn.RANK.EQ(AG4,$AG$4:$AG$212,1) -> 66 | AJ4: =COUNTIF($AI$4:$AI$212,AI4)+AI4-1 -> 66 | AK4: =MIN(AG4*$AJ$3/AJ4,1) -> 0.0012681585 | AL4: =MIN(AK4,IFERROR(VLOOKUP(AJ4+1,$AJ$4:$AL$212,3,FALSE),1)) -> 0.0012517624 | AM4: =IF(AL4<0.05,"**",IF(AL4<0.1,"*","")) -> **
A5: Pos | B5: 33 | C5: 426.35692 | D5: 5.0254647 | E5: 1 | F5: Car(18:1) | G5: Car | I5: 152973 | J5: 111467 | K5: 226070 | L5: 129943 | M5: 94314 | N5: 171489 | O5: 69710 | Q5: 4779 | R5: 18968 | S5: 7820 | T5: 10453 | U5: 24161 | V5: 24386 | W5: 14061 | Y5: 22 | Z5: 75872 | AA5: 67132 | AB5: 61739 | AC5: =IFERROR(STDEV(Z5:AB5)/AVERAGE(Z5:AB5),0) -> 0.10450537 | AD5: =AVERAGE(I5:O5) -> 136566.57 | AE5: =AVERAGE(Q5:W5) -> 14946.857 | AF5: =AE5/AD5 -> 0.10944741 | AG5: =TTEST(I5:O5,Q5:W5,2,3) -> 0.00076311408 | AH5: =IF(AG5<0.001,"***",IF(AG5<0.01,"**",IF(AG5<0.05,"*","-"))) -> *** | AI5: =_xlfn.RANK.EQ(AG5,$AG$4:$AG$212,1) -> 77 | AJ5: =COUNTIF($AI$4:$AI$212,AI5)+AI5-1 -> 77 | AK5: =MIN(AG5*$AJ$3/AJ5,1) -> 0.0020713096 | AL5: =MIN(AK5,IFERROR(VLOOKUP(AJ5+1,$AJ$4:$AL$212,3,FALSE),1)) -> 0.0020713096 | AM5: =IF(AL5<0.05,"**",IF(AL5<0.1,"*","")) -> **
A6: Pos | B6: 40 | C6: 424.34146 | D6: 4.5945067 | E6: 1 | F6: Car(18:2) | G6: Car | I6: 181841 | J6: 107376 | K6: 175622 | L6: 146020 | M6: 140857 | N6: 150531 | O6: 81718 | Q6: 4553 | R6: 21520 | S6: 6252 | T6: 10307 | U6: 30868 | V6: 23698 | W6: 20051 | Y6: 145 | Z6: 67025 | AA6: 54473 | AB6: 58321 | AC6: =IFERROR(STDEV(Z6:AB6)/AVERAGE(Z6:AB6),0) -> 0.10728535 | AD6: =AVERAGE(I6:O6) -> 140566.43 | AE6: =AVERAGE(Q6:W6) -> 16749.857 | AF6: =AE6/AD6 -> 0.11915973 | AG6: =TTEST(I6:O6,Q6:W6,2,3) -> 5.1125865e-05 | AH6: =IF(AG6<0.001,"***",IF(AG6<0.01,"**",IF(AG6<0.05,"*","-"))) -> *** | AI6: =_xlfn.RANK.EQ(AG6,$AG$4:$AG$212,1) -> 26 | AJ6: =COUNTIF($AI$4:$AI$212,AI6)+AI6-1 -> 26 | AK6: =MIN(AG6*$AJ$3/AJ6,1) -> 0.0004109733 | AL6: =MIN(AK6,IFERROR(VLOOKUP(AJ6+1,$AJ$4:$AL$212,3,FALSE),1)) -> 0.0004039416 | AM6: =IF(AL6<0.05,"**",IF(AL6<0.1,"*","")) -> **
A7: Pos | B7: 63 | C7: 372.31003 | D7: 4.1418108 | E7: 1 | F7: Car(14:0) | G7: Car | I7: 69833 | J7: 59649 | K7: 99611 | L7: 82093 | M7: 81212 | N7: 95517 | O7: 33749 | Q7: 4176 | R7: 13398 | S7: 7752 | T7: 6685 | U7: 8731 | V7: 14383 | W7: 8847 | Y7: 514 | Z7: 41031 | AA7: 41382 | AB7: 35139 | AC7: =IFERROR(STDEV(Z7:AB7)/AVERAGE(Z7:AB7),0) -> 0.089512714 | AD7: =AVERAGE(I7:O7) -> 74523.429 | AE7: =AVERAGE(Q7:W7) -> 9138.8571 | AF7: =AE7/AD7 -> 0.12263066 | AG7: =TTEST(I7:O7,Q7:W7,2,3) -> 0.0002219838 | AH7: =IF(AG7<0.001,"***",IF(AG7<0.01,"**",IF(AG7<0.05,"*","-"))) -> *** | AI7: =_xlfn.RANK.EQ(AG7,$AG$4:$AG$212,1) -> 55 | AJ7: =COUNTIF($AI$4:$AI$212,AI7)+AI7-1 -> 55 | AK7: =MIN(AG7*$AJ$3/AJ7,1) -> 0.00084353842 | AL7: =MIN(AK7,IFERROR(VLOOKUP(AJ7+1,$AJ$4:$AL$212,3,FALSE),1)) -> 0.00084353842 | AM7: =IF(AL7<0.05,"**",IF(AL7<0.1,"*","")) -> **
A8: Pos | B8: 90 | C8: 396.31021 | D8: 3.9289125 | E8: 1 | F8: Car(16:2) | G8: Car | I8: 54211 | J8: 35890 | K8: 61056 | L8: 60283 | M8: 62243 | N8: 63139 | O8: 32495 | Q8: 1759 | R8: 9860 | S8: 3698 | T8: 4311 | U8: 9002 | V8: 14526 | W8: 6958 | Y8: 4 | Z8: 23432 | AA8: 24821 | AB8: 20224 | AC8: =IFERROR(STDEV(Z8:AB8)/AVERAGE(Z8:AB8),0) -> 0.10329239 | AD8: =AVERAGE(I8:O8) -> 52759.571 | AE8: =AVERAGE(Q8:W8) -> 7159.1429 | AF8: =AE8/AD8 -> 0.13569373 | AG8: =TTEST(I8:O8,Q8:W8,2,3) -> 3.8336435e-05 | AH8: =IF(AG8<0.001,"***",IF(AG8<0.01,"**",IF(AG8<0.05,"*","-"))) -> *** | AI8: =_xlfn.RANK.EQ(AG8,$AG$4:$AG$212,1) -> 20 | AJ8: =COUNTIF($AI$4:$AI$212,AI8)+AI8-1 -> 20 | AK8: =MIN(AG8*$AJ$3/AJ8,1) -> 0.00040061575 | AL8: =MIN(AK8,IFERROR(VLOOKUP(AJ8+1,$AJ$4:$AL$212,3,FALSE),1)) -> 0.00038828708 | AM8: =IF(AL8<0.05,"**",IF(AL8<0.1,"*","")) -> **
A9: Pos | B9: 96 | C9: 398.32541 | D9: 4.3869373 | E9: 1 | F9: Car(16:1) | G9: Car | I9: 42143 | J9: 31520 | K9: 59273 | L9: 49579 | M9: 48290 | N9: 53604 | O9: 24597 | Q9: 2151 | R9: 7933 | S9: 1822 | T9: 3336 | U9: 4941 | V9: 8969 | W9: 5510 | Y9: 133 | Z9: 20333 | AA9: 20491 | AB9: 17405 | AC9: =IFERROR(STDEV(Z9:AB9)/AVERAGE(Z9:AB9),0) -> 0.08953728 | AD9: =AVERAGE(I9:O9) -> 44143.714 | AE9: =AVERAGE(Q9:W9) -> 4951.7143 | AF9: =AE9/AD9 -> 0.11217258 | AG9: =TTEST(I9:O9,Q9:W9,2,3) -> 0.00010619744 | AH9: =IF(AG9<0.001,"***",IF(AG9<0.01,"**",IF(AG9<0.05,"*","-"))) -> *** | AI9: =_xlfn.RANK.EQ(AG9,$AG$4:$AG$212,1) -> 43 | AJ9: =COUNTIF($AI$4:$AI$212,AI9)+AI9-1 -> 43 | AK9: =MIN(AG9*$AJ$3/AJ9,1) -> 0.00051616896 | AL9: =MIN(AK9,IFERROR(VLOOKUP(AJ9+1,$AJ$4:$AL$212,3,FALSE),1)) -> 0.00051616896 | AM9: =IF(AL9<0.05,"**",IF(AL9<0.1,"*","")) -> **
A10: Pos | B10: 103 | C10: 428.37203 | D10: 5.5133127 | E10: 1 | F10: Car(18:0) | G10: Car | I10: 48004 | J10: 33143 | K10: 51804 | L10: 28598 | M10: 35217 | N10: 46645 | O10: 28330 | Q10: 2345 | R10: 5836 | S10: 4076 | T10: 3346 | U10: 5200 | V10: 9577 | W10: 4568 | Y10: 697 | Z10: 22201 | AA10: 24475 | AB10: 17370 | AC10: =IFERROR(STDEV(Z10:AB10)/AVERAGE(Z10:AB10),0) -> 0.16995795 | AD10: =AVERAGE(I10:O10) -> 38820.143 | AE10: =AVERAGE(Q10:W10) -> 4992.5714 | AF10: =AE10/AD10 -> 0.12860776 | AG10: =TTEST(I10:O10,Q10:W10,2,3) -> 6.057944e-05 | AH10: =IF(AG10<0.001,"***",IF(AG10<0.01,"**",IF(AG10<0.05,"*","-"))) -> *** | AI10: =_xlfn.RANK.EQ(AG10,$AG$4:$AG$212,1) -> 31 | AJ10: =COUNTIF($AI$4:$AI$212,AI10)+AI10-1 -> 31 | AK10: =MIN(AG10*$AJ$3/AJ10,1) -> 0.00040842268 | AL10: =MIN(AK10,IFERROR(VLOOKUP(AJ10+1,$AJ$4:$AL$212,3,FALSE),1)) -> 0.00040842268 | AM10: =IF(AL10<0.05,"**",IF(AL10<0.1,"*","")) -> **
A11: Pos | B11: 119 | C11: 452.37168 | D11: 5.2085852 | E11: 1 | F11: Car(20:2) | G11: Car | I11: 38230 | J11: 22021 | K11: 42870 | L11: 20924 | M11: 19044 | N11: 24213 | O11: 17309 | Q11: 1676 | R11: 3359 | S11: 1937 | T11: 3631 | U11: 7784 | V11: 6954 | W11: 2468 | Y11: 782 | Z11: 14623 | AA11: 13153 | AB11: 13384 | AC11: =IFERROR(STDEV(Z11:AB11)/AVERAGE(Z11:AB11),0) -> 0.057616929 | AD11: =AVERAGE(I11:O11) -> 26373 | AE11: =AVERAGE(Q11:W11) -> 3972.7143 | AF11: =AE11/AD11 -> 0.15063566 | AG11: =TTEST(I11:O11,Q11:W11,2,3) -> 0.0008142871 | AH11: =IF(AG11<0.001,"***",IF(AG11<0.01,"**",IF(AG11<0.05,"*","-"))) -> *** | AI11: =_xlfn.RANK.EQ(AG11,$AG$4:$AG$212,1) -> 79 | AJ11: =COUNTIF($AI$4:$AI$212,AI11)+AI11-1 -> 79 | AK11: =MIN(AG11*$AJ$3/AJ11,1) -> 0.0021542532 | AL11: =MIN(AK11,IFERROR(VLOOKUP(AJ11+1,$AJ$4:$AL$212,3,FALSE),1)) -> 0.002143644 | AM11: =IF(AL11<0.05,"**",IF(AL11<0.1,"*","")) -> **
A12: Pos | B12: 126 | C12: 454.38774 | D12: 5.6046382 | E12: 1 | F12: Car(20:1) | G12: Car | I12: 30800 | J12: 19516 | K12: 39975 | L12: 15335 | M12: 13671 | N12: 21722 | O12: 15958 | Q12: 665 | R12: 2578 | S12: 898 | T12: 1565 | U12: 3227 | V12: 4281 | W12: 1725 | Y12: 27 | Z12: 11808 | AA12: 10952 | AB12: 8846 | AC12: =IFERROR(STDEV(Z12:AB12)/AVERAGE(Z12:AB12),0) -> 0.14468701 | AD12: =AVERAGE(I12:O12) -> 22425.286 | AE12: =AVERAGE(Q12:W12) -> 2134.1429 | AF12: =AE12/AD12 -> 0.095166808 | AG12: =TTEST(I12:O12,Q12:W12,2,3) -> 0.0013110192 | AH12: =IF(AG12<0.001,"***",IF(AG12<0.01,"**",IF(AG12<0.05,"*","-"))) -> ** | AI12: =_xlfn.RANK.EQ(AG12,$AG$4:$AG$212,1) -> 88 | AJ12: =COUNTIF($AI$4:$AI$212,AI12)+AI12-1 -> 88 | AK12: =MIN(AG12*$AJ$3/AJ12,1) -> 0.0031136706 | AL12: =MIN(AK12,IFERROR(VLOOKUP(AJ12+1,$AJ$4:$AL$212,3,FALSE),1)) -> 0.0031136706 | AM12: =IF(AL12<0.05,"**",IF(AL12<0.1,"*","")) -> **
A13: Pos | B13: 130 | C13: 344.27832 | D13: 3.2845657 | E13: 1 | F13: Car(12:0) | G13: Car | I13: 19515 | J13: 16965 | K13: 30901 | L13: 38521 | M13: 33113 | N13: 27218 | O13: 15297 | Q13: 2469 | R13: 7184 | S13: 2695 | T13: 3004 | U13: 2331 | V13: 5777 | W13: 4610 | Y13: 110 | Z13: 14519 | AA13: 13470 | AB13: 11141 | AC13: =IFERROR(STDEV(Z13:AB13)/AVERAGE(Z13:AB13),0) -> 0.132554 | AD13: =AVERAGE(I13:O13) -> 25932.857 | AE13: =AVERAGE(Q13:W13) -> 4010 | AF13: =AE13/AD13 -> 0.15463009 | AG13: =TTEST(I13:O13,Q13:W13,2,3) -> 0.00048280746 | AH13: =IF(AG13<0.001,"***",IF(AG13<0.01,"**",IF(AG13<0.05,"*","-"))) -> *** | AI13: =_xlfn.RANK.EQ(AG13,$AG$4:$AG$212,1) -> 70 | AJ13: =COUNTIF($AI$4:$AI$212,AI13)+AI13-1 -> 70 | AK13: =MIN(AG13*$AJ$3/AJ13,1) -> 0.0014415251 | AL13: =MIN(AK13,IFERROR(VLOOKUP(AJ13+1,$AJ$4:$AL$212,3,FALSE),1)) -> 0.0014415251 | AM13: =IF(AL13<0.05,"**",IF(AL13<0.1,"*","")) -> **
A14: Pos | B14: 174 | C14: 370.29396 | D14: 3.5954321 | E14: 1 | F14: Car(14:1) | G14: Car | I14: 12001 | J14: 12880 | K14: 25573 | L14: 27632 | M14: 17219 | N14: 18598 | O14: 11369 | Q14: 1206 | R14: 4857 | S14: 1587 | T14: 2053 | U14: 2259 | V14: 4798 | W14: 3675 | Y14: 85 | Z14: 10607 | AA14: 10931 | AB14: 9652 | AC14: =IFERROR(STDEV(Z14:AB14)/AVERAGE(Z14:AB14),0) -> 0.063956685 | AD14: =AVERAGE(I14:O14) -> 17896 | AE14: =AVERAGE(Q14:W14) -> 2919.2857 | AF14: =AE14/AD14 -> 0.16312504 | AG14: =TTEST(I14:O14,Q14:W14,2,3) -> 0.00073139059 | AH14: =IF(AG14<0.001,"***",IF(AG14<0.01,"**",IF(AG14<0.05,"*","-"))) -> *** | AI14: =_xlfn.RANK.EQ(AG14,$AG$4:$AG$212,1) -> 75 | AJ14: =COUNTIF($AI$4:$AI$212,AI14)+AI14-1 -> 75 | AK14: =MIN(AG14*$AJ$3/AJ14,1) -> 0.0020381418 | AL14: =MIN(AK14,IFERROR(VLOOKUP(AJ14+1,$AJ$4:$AL$212,3,FALSE),1)) -> 0.0020267022 | AM14: =IF(AL14<0.05,"**",IF(AL14<0.1,"*","")) -> **
A15: Pos | B15: 267 | C15: 316.24681 | D15: 2.2618015 | E15: 1 | F15: Car(10:0) | G15: Car | I15: 4988 | J15: 7244 | K15: 10638 | L15: 15285 | M15: 8345 | N15: 7325 | O15: 5085 | Q15: 1005 | R15: 2725 | S15: 1301 | T15: 1351 | U15: 1022 | V15: 2158 | W15: 2449 | Y15: 459 | Z15: 5106 | AA15: 5607 | AB15: 5489 | AC15: =IFERROR(STDEV(Z15:AB15)/AVERAGE(Z15:AB15),0) -> 0.048497804 | AD15: =AVERAGE(I15:O15) -> 8415.7143 | AE15: =AVERAGE(Q15:W15) -> 1715.8571 | AF15: =AE15/AD15 -> 0.20388729 | AG15: =TTEST(I15:O15,Q15:W15,2,3) -> 0.0023464248 | AH15: =IF(AG15<0.001,"***",IF(AG15<0.01,"**",IF(AG15<0.05,"*","-"))) -> ** | AI15: =_xlfn.RANK.EQ(AG15,$AG$4:$AG$212,1) -> 95 | AJ15: =COUNTIF($AI$4:$AI$212,AI15)+AI15-1 -> 95 | AK15: =MIN(AG15*$AJ$3/AJ15,1) -> 0.0051621345 | AL15: =MIN(AK15,IFERROR(VLOOKUP(AJ15+1,$AJ$4:$AL$212,3,FALSE),1)) -> 0.0051621345 | AM15: =IF(AL15<0.05,"**",IF(AL15<0.1,"*","")) -> **
... A212: Pos | B212: 112 | C212: 675.67635 | D212: 15.962624 | E212: 1 | F212: IS(ChE_d7)(18:1) | G212: IS | I212: 24068 | J212: 21225 | K212: 34869 | L212: 24185 | M212: 23764 | N212: 26569 | O212: 26868 | Q212: 19419 | R212: 29259 | S212: 19450 | T212: 26422 | U212: 22157 | V212: 26335 | W212: 30001 | Y212: 46752 | Z212: 22907 | AA212: 23667 | AB212: 20701 | AC212: =IFERROR(STDEV(Z212:AB212)/AVERAGE(Z212:AB212),0) -> 0.068701322 | AD212: =AVERAGE(I212:O212) -> 25935.429 | AE212: =AVERAGE(Q212:W212) -> 24720.429 | AF212: =AE212/AD212 -> 0.95315289 | AG212: =TTEST(I212:O212,Q212:W212,2,3) -> 0.61380266 | AH212: =IF(AG212<0.001,"***",IF(AG212<0.01,"**",IF(AG212<0.05,"*","-"))) -> - | AI212: =_xlfn.RANK.EQ(AG212,$AG$4:$AG$212,1) -> 193 | AJ212: =COUNTIF($AI$4:$AI$212,AI212)+AI212-1 -> 193 | AK212: =MIN(AG212*$AJ$3/AJ212,1) -> 0.66468786 | AL212: =MIN(AK212,IFERROR(VLOOKUP(AJ212+1,$AJ$4:$AL$212,3,FALSE),1)) -> 0.66468786 | AM212: =IF(AL212<0.05,"**",IF(AL212<0.1,"*",""))
F214: Detection criteria: | AG214: Welch-T Significance | AL214: FDR Significance
F215: height > blank | AG215: P<0.001 : *** | AL215: Q<0.05 : **
F216: height > 100 cps | AG216: P<0.010 : ** | AL216: Q<0.10 : *
F217: RSD in QC samples<25% | AG217: P<0.050 : *

Sheet Lipid class level
A1: ※検出数および累計値はQCRSD | L1: =(AU1-1)/(AU1+1) -> 0.8 | AD1: Control | AL1: HFpEF | AT1: B | AU1: 9 | AV1: 倍以上 | AW1: ●●●
A2: 25%以下のもののみを集計。 | D2: Control | E2: Control | F2: Control | G2: Control | H2: Control | I2: Control | J2: Control | L2: HFpEF | M2: HFpEF | N2: HFpEF | O2: HFpEF | P2: HFpEF | Q2: HFpEF | R2: HFpEF | T2: Blank | U2: QC | V2: QC | W2: QC | X2: QC | Y2: Mean | AB2: Welch-T | AD2: 1 | AE2: 2 | AF2: 3 | AG2: 4 | AH2: 5 | AI2: 6 | AJ2: 7 | AL2: 8 | AM2: 9 | AN2: 1 | AO2: 1 | AP2: 1 | AQ2: 1 | AR2: 1 | AT2: l | AU2: 6 | AV2: 倍以上 | AW2: ●●
A3: Polarity | B3: Class | C3: Counts | D3: 1 | E3: 2 | F3: 3 | G3: 4 | H3: 5 | I3: 6 | J3: 7 | L3: 8 | M3: 9 | N3: 10 | O3: 11 | P3: 12 | Q3: 13 | R3: 14 | T3: Blank | U3: Neg1/Pos4 | V3: Neg2/Pos5 | W3: Neg3/Pos6 | X3: RSD | Y3: Control | Z3: HFpEF | AA3: Fold change | AB3: P-value | AC3: Significance | AN3: 0 | AO3: 1 | AP3: 2 | AQ3: 3 | AR3: 4 | AT3: k | AU3: 3 | AV3: 倍以上 | AW3: ●
A4: Neg | B4: FA | C4: =COUNTIFS('Molecules_Negative-ion mode'!$G$4:$G$390,'Lipid class level'!$B4) -> 14 | D4: =SUMIFS('Molecules_Negative-ion mode'!I$4:I$390,'Molecules_Negative-ion mode'!$G$4:$G$390,'Lipid class level'!$B4) -> 159841 | E4: =SUMIFS('Molecules_Negative-ion mode'!J$4:J$390,'Molecules_Negative-ion mode'!$G$4:$G$390,'Lipid class level'!$B4) -> 126795 | F4: =SUMIFS('Molecules_Negative-ion mode'!K$4:K$390,'Molecules_Negative-ion mode'!$G$4:$G$390,'Lipid class level'!$B4) -> 118899 | G4: =SUMIFS('Molecules_Negative-ion mode'!L$4:L$390,'Molecules_Negative-ion mode'!$G$4:$G$390,'Lipid class level'!$B4) -> 89086 | H4: =SUMIFS('Molecules_Negative-ion mode'!M$4:M$390,'Molecules_Negative-ion mode'!$G$4:$G$390,'Lipid class level'!$B4) -> 119438 | I4: =SUMIFS('Molecules_Negative-ion mode'!N$4:N$390,'Molecules_Negative-ion mode'!$G$4:$G$390,'Lipid class level'!$B4) -> 172844 | J4: =SUMIFS('Molecules_Negative-ion mode'!O$4:O$390,'Molecules_Negative-ion mode'!$G$4:$G$390,'Lipid class level'!$B4) -> 148790 | L4: =SUMIFS('Molecules_Negative-ion mode'!Q$4:Q$390,'Molecules_Negative-ion mode'!$G$4:$G$390,'Lipid class level'!$B4) -> 138379 | M4: =SUMIFS('Molecules_Negative-ion mode'!R$4:R$390,'Molecules_Negative-ion mode'!$G$4:$G$390,'Lipid class level'!$B4) -> 335001 | N4: =SUMIFS('Molecules_Negative-ion mode'!S$4:S$390,'Molecules_Negative-ion mode'!$G$4:$G$390,'Lipid class level'!$B4) -> 181213 | O4: =SUMIFS('Molecules_Negative-ion mode'!T$4:T$390,'Molecules_Negative-ion mode'!$G$4:$G$390,'Lipid class level'!$B4) -> 165774 | P4: =SUMIFS('Molecules_Negative-ion mode'!U$4:U$390,'Molecules_Negative-ion mode'!$G$4:$G$390,'Lipid class level'!$B4) -> 295956 | Q4: =SUMIFS('Molecules_Negative-ion mode'!V$4:V$390,'Molecules_Negative-ion mode'!$G$4:$G$390,'Lipid class level'!$B4) -> 157409 | R4: =SUMIFS('Molecules_Negative-ion mode'!W$4:W$390,'Molecules_Negative-ion mode'!$G$4:$G$390,'Lipid class level'!$B4) -> 252410 | T4: =SUMIFS('Molecules_Negative-ion mode'!Y$4:Y$390,'Molecules_Negative-ion mode'!$G$4:$G$390,'Lipid class level'!$B4) -> 21625 | U4: =SUMIFS('Molecules_Negative-ion mode'!Z$4:Z$390,'Molecules_Negative-ion mode'!$G$4:$G$390,'Lipid class level'!$B4) -> 172992 | V4: =SUMIFS('Molecules_Negative-ion mode'!AA$4:AA$390,'Molecules_Negative-ion mode'!$G$4:$G$390,'Lipid class level'!$B4) -> 196484 | W4: =SUMIFS('Molecules_Negative-ion mode'!AB$4:AB$390,'Molecules_Negative-ion mode'!$G$4:$G$390,'Lipid class level'!$B4) -> 208956 | X4: =IFERROR(STDEV(U4:W4)/AVERAGE(U4:W4),0) -> 0.09471066 | Y4: =AVERAGE(D4:J4) -> 133670.43 | Z4: =AVERAGE(L4:R4) -> 218020.29 | AA4: =Z4/Y4 -> 1.6310286 | AB4: =TTEST(D4:J4,L4:R4,2,3) -> 0.026752846 | AC4: =IF(AB4<0.001,"***",IF(AB4<0.01,"**",IF(AB4<0.05,"*","-"))) -> *
A5: Neg | B5: FA[O] | C5: =COUNTIFS('Molecules_Negative-ion mode'!$G$4:$G$390,'Lipid class level'!$B5) -> 2 | D5: =SUMIFS('Molecules_Negative-ion mode'!I$4:I$390,'Molecules_Negative-ion mode'!$G$4:$G$390,'Lipid class level'!$B5) -> 1859 | E5: =SUMIFS('Molecules_Negative-ion mode'!J$4:J$390,'Molecules_Negative-ion mode'!$G$4:$G$390,'Lipid class level'!$B5) -> 4489 | F5: =SUMIFS('Molecules_Negative-ion mode'!K$4:K$390,'Molecules_Negative-ion mode'!$G$4:$G$390,'Lipid class level'!$B5) -> 1537 | G5: =SUMIFS('Molecules_Negative-ion mode'!L$4:L$390,'Molecules_Negative-ion mode'!$G$4:$G$390,'Lipid class level'!$B5) -> 2019 | H5: =SUMIFS('Molecules_Negative-ion mode'!M$4:M$390,'Molecules_Negative-ion mode'!$G$4:$G$390,'Lipid class level'!$B5) -> 2925 | I5: =SUMIFS('Molecules_Negative-ion mode'!N$4:N$390,'Molecules_Negative-ion mode'!$G$4:$G$390,'Lipid class level'!$B5) -> 9424 | J5: =SUMIFS('Molecules_Negative-ion mode'!O$4:O$390,'Molecules_Negative-ion mode'!$G$4:$G$390,'Lipid class level'!$B5) -> 5031 | L5: =SUMIFS('Molecules_Negative-ion mode'!Q$4:Q$390,'Molecules_Negative-ion mode'!$G$4:$G$390,'Lipid class level'!$B5) -> 3242 | M5: =SUMIFS('Molecules_Negative-ion mode'!R$4:R$390,'Molecules_Negative-ion mode'!$G$4:$G$390,'Lipid class level'!$B5) -> 10372 | N5: =SUMIFS('Molecules_Negative-ion mode'!S$4:S$390,'Molecules_Negative-ion mode'!$G$4:$G$390,'Lipid class level'!$B5) -> 9853 | O5: =SUMIFS('Molecules_Negative-ion mode'!T$4:T$390,'Molecules_Negative-ion mode'!$G$4:$G$390,'Lipid class level'!$B5) -> 2632 | P5: =SUMIFS('Molecules_Negative-ion mode'!U$4:U$390,'Molecules_Negative-ion mode'!$G$4:$G$390,'Lipid class level'!$B5) -> 10383 | Q5: =SUMIFS('Molecules_Negative-ion mode'!V$4:V$390,'Molecules_Negative-ion mode'!$G$4:$G$390,'Lipid class level'!$B5) -> 9119 | R5: =SUMIFS('Molecules_Negative-ion mode'!W$4:W$390,'Molecules_Negative-ion mode'!$G$4:$G$390,'Lipid class level'!$B5) -> 1760 | T5: =SUMIFS('Molecules_Negative-ion mode'!Y$4:Y$390,'Molecules_Negative-ion mode'!$G$4:$G$390,'Lipid class level'!$B5) -> 1053 | U5: =SUMIFS('Molecules_Negative-ion mode'!Z$4:Z$390,'Molecules_Negative-ion mode'!$G$4:$G$390,'Lipid class level'!$B5) -> 5797 | V5: =SUMIFS('Molecules_Negative-ion mode'!AA$4:AA$390,'Molecules_Negative-ion mode'!$G$4:$G$390,'Lipid class level'!$B5) -> 7198 | W5: =SUMIFS('Molecules_Negative-ion mode'!AB$4:AB$390,'Molecules_Negative-ion mode'!$G$4:$G$390,'Lipid class level'!$B5) -> 6347 | X5: =IFERROR(STDEV(U5:W5)/AVERAGE(U5:W5),0) -> 0.10948224 | Y5: =AVERAGE(D5:J5) -> 3897.7143 | Z5: =AVERAGE(L5:R5) -> 6765.8571 | AA5: =Z5/Y5 -> 1.7358525 | AB5: =TTEST(D5:J5,L5:R5,2,3) -> 0.14796926 | AC5: =IF(AB5<0.001,"***",IF(AB5<0.01,"**",IF(AB5<0.05,"*","-"))) -> -
A6: Neg | B6: CoA | C6: =COUNTIFS('Molecules_Negative-ion mode'!$G$4:$G$390,'Lipid class level'!$B6) -> 21 | D6: =SUMIFS('Molecules_Negative-ion mode'!I$4:I$390,'Molecules_Negative-ion mode'!$G$4:$G$390,'Lipid class level'!$B6) -> 61502 | E6: =SUMIFS('Molecules_Negative-ion mode'!J$4:J$390,'Molecules_Negative-ion mode'!$G$4:$G$390,'Lipid class level'!$B6) -> 66697 | F6: =SUMIFS('Molecules_Negative-ion mode'!K$4:K$390,'Molecules_Negative-ion mode'!$G$4:$G$390,'Lipid class level'!$B6) -> 40592 | G6: =SUMIFS('Molecules_Negative-ion mode'!L$4:L$390,'Molecules_Negative-ion mode'!$G$4:$G$390,'Lipid class level'!$B6) -> 29016 | H6: =SUMIFS('Molecules_Negative-ion mode'!M$4:M$390,'Molecules_Negative-ion mode'!$G$4:$G$390,'Lipid class level'!$B6) -> 108975 | I6: =SUMIFS('Molecules_Negative-ion mode'!N$4:N$390,'Molecules_Negative-ion mode'!$G$4:$G$390,'Lipid class level'!$B6) -> 120262 | J6: =SUMIFS('Molecules_Negative-ion mode'!O$4:O$390,'Molecules_Negative-ion mode'!$G$4:$G$390,'Lipid class level'!$B6) -> 91186 | L6: =SUMIFS('Molecules_Negative-ion mode'!Q$4:Q$390,'Molecules_Negative-ion mode'!$G$4:$G$390,'Lipid class level'!$B6) -> 23262 | M6: =SUMIFS('Molecules_Negative-ion mode'!R$4:R$390,'Molecules_Negative-ion mode'!$G$4:$G$390,'Lipid class level'!$B6) -> 37852 | N6: =SUMIFS('Molecules_Negative-ion mode'!S$4:S$390,'Molecules_Negative-ion mode'!$G$4:$G$390,'Lipid class level'!$B6) -> 9502 | O6: =SUMIFS('Molecules_Negative-ion mode'!T$4:T$390,'Molecules_Negative-ion mode'!$G$4:$G$390,'Lipid class level'!$B6) -> 22380 | P6: =SUMIFS('Molecules_Negative-ion mode'!U$4:U$390,'Molecules_Negative-ion mode'!$G$4:$G$390,'Lipid class level'!$B6) -> 40245 | Q6: =SUMIFS('Molecules_Negative-ion mode'!V$4:V$390,'Molecules_Negative-ion mode'!$G$4:$G$390,'Lipid class level'!$B6) -> 30698 | R6: =SUMIFS('Molecules_Negative-ion mode'!W$4:W$390,'Molecules_Negative-ion mode'!$G$4:$G$390,'Lipid class level'!$B6) -> 36089 | T6: =SUMIFS('Molecules_Negative-ion mode'!Y$4:Y$390,'Molecules_Negative-ion mode'!$G$4:$G$390,'Lipid class level'!$B6) -> 145 | U6: =SUMIFS('Molecules_Negative-ion mode'!Z$4:Z$390,'Molecules_Negative-ion mode'!$G$4:$G$390,'Lipid class level'!$B6) -> 46983 | V6: =SUMIFS('Molecules_Negative-ion mode'!AA$4:AA$390,'Molecules_Negative-ion mode'!$G$4:$G$390,'Lipid class level'!$B6) -> 51051 | W6: =SUMIFS('Molecules_Negative-ion mode'!AB$4:AB$390,'Molecules_Negative-ion mode'!$G$4:$G$390,'Lipid class level'!$B6) -> 53584 | X6: =IFERROR(STDEV(U6:W6)/AVERAGE(U6:W6),0) -> 0.065891509 | Y6: =AVERAGE(D6:J6) -> 74032.857 | Z6: =AVERAGE(L6:R6) -> 28575.429 | AA6: =Z6/Y6 -> 0.38598306 | AB6: =TTEST(D6:J6,L6:R6,2,3) -> 0.011688283 | AC6: =IF(AB6<0.001,"***",IF(AB6<0.01,"**",IF(AB6<0.05,"*","-"))) -> *
A7: Pos | B7: Car | C7: =COUNTIFS('Molecules_Positive ion mode'!$G$4:$G$390,'Lipid class level'!$B7) -> 33 | D7: =SUMIFS('Molecules_Positive ion mode'!I$4:I$390,'Molecules_Positive ion mode'!$G$4:$G$390,'Lipid class level'!$B7) -> 889834 | E7: =SUMIFS('Molecules_Positive ion mode'!J$4:J$390,'Molecules_Positive ion mode'!$G$4:$G$390,'Lipid class level'!$B7) -> 657263 | F7: =SUMIFS('Molecules_Positive ion mode'!K$4:K$390,'Molecules_Positive ion mode'!$G$4:$G$390,'Lipid class level'!$B7) -> 1166621 | G7: =SUMIFS('Molecules_Positive ion mode'!L$4:L$390,'Molecules_Positive ion mode'!$G$4:$G$390,'Lipid class level'!$B7) -> 886934 | H7: =SUMIFS('Molecules_Positive ion mode'!M$4:M$390,'Molecules_Positive ion mode'!$G$4:$G$390,'Lipid class level'!$B7) -> 785896 | I7: =SUMIFS('Molecules_Positive ion mode'!N$4:N$390,'Molecules_Positive ion mode'!$G$4:$G$390,'Lipid class level'!$B7) -> 964660 | J7: =SUMIFS('Molecules_Positive ion mode'!O$4:O$390,'Molecules_Positive ion mode'!$G$4:$G$390,'Lipid class level'!$B7) -> 490435 | L7: =SUMIFS('Molecules_Positive ion mode'!Q$4:Q$390,'Molecules_Positive ion mode'!$G$4:$G$390,'Lipid class level'!$B7) -> 47149 | M7: =SUMIFS('Molecules_Positive ion mode'!R$4:R$390,'Molecules_Positive ion mode'!$G$4:$G$390,'Lipid class level'!$B7) -> 156533 | N7: =SUMIFS('Molecules_Positive ion mode'!S$4:S$390,'Molecules_Positive ion mode'!$G$4:$G$390,'Lipid class level'!$B7) -> 69039 | O7: =SUMIFS('Molecules_Positive ion mode'!T$4:T$390,'Molecules_Positive ion mode'!$G$4:$G$390,'Lipid class level'!$B7) -> 82022 | P7: =SUMIFS('Molecules_Positive ion mode'!U$4:U$390,'Molecules_Positive ion mode'!$G$4:$G$390,'Lipid class level'!$B7) -> 143364 | Q7: =SUMIFS('Molecules_Positive ion mode'!V$4:V$390,'Molecules_Positive ion mode'!$G$4:$G$390,'Lipid class level'!$B7) -> 172934 | R7: =SUMIFS('Molecules_Positive ion mode'!W$4:W$390,'Molecules_Positive ion mode'!$G$4:$G$390,'Lipid class level'!$B7) -> 122179 | T7: =SUMIFS('Molecules_Positive ion mode'!Y$4:Y$390,'Molecules_Positive ion mode'!$G$4:$G$390,'Lipid class level'!$B7) -> 6482 | U7: =SUMIFS('Molecules_Positive ion mode'!Z$4:Z$390,'Molecules_Positive ion mode'!$G$4:$G$390,'Lipid class level'!$B7) -> 460717 | V7: =SUMIFS('Molecules_Positive ion mode'!AA$4:AA$390,'Molecules_Positive ion mode'!$G$4:$G$390,'Lipid class level'!$B7) -> 422642 | W7: =SUMIFS('Molecules_Positive ion mode'!AB$4:AB$390,'Molecules_Positive ion mode'!$G$4:$G$390,'Lipid class level'!$B7) -> 388328 | X7: =IFERROR(STDEV(U7:W7)/AVERAGE(U7:W7),0) -> 0.085423803 | Y7: =AVERAGE(D7:J7) -> 834520.43 | Z7: =AVERAGE(L7:R7) -> 113317.14 | AA7: =Z7/Y7 -> 0.13578714 | AB7: =TTEST(D7:J7,L7:R7,2,3) -> 8.4926837e-05 | AC7: =IF(AB7<0.001,"***",IF(AB7<0.01,"**",IF(AB7<0.05,"*","-"))) -> ***
A8: Pos | B8: Car[O] | C8: =COUNTIFS('Molecules_Positive ion mode'!$G$4:$G$390,'Lipid class level'!$B8) -> 15 | D8: =SUMIFS('Molecules_Positive ion mode'!I$4:I$390,'Molecules_Positive ion mode'!$G$4:$G$390,'Lipid class level'!$B8) -> 87566 | E8: =SUMIFS('Molecules_Positive ion mode'!J$4:J$390,'Molecules_Positive ion mode'!$G$4:$G$390,'Lipid class level'!$B8) -> 69137 | F8: =SUMIFS('Molecules_Positive ion mode'!K$4:K$390,'Molecules_Positive ion mode'!$G$4:$G$390,'Lipid class level'!$B8) -> 129720 | G8: =SUMIFS('Molecules_Positive ion mode'!L$4:L$390,'Molecules_Positive ion mode'!$G$4:$G$390,'Lipid class level'!$B8) -> 92743 | H8: =SUMIFS('Molecules_Positive ion mode'!M$4:M$390,'Molecules_Positive ion mode'!$G$4:$G$390,'Lipid class level'!$B8) -> 59991 | I8: =SUMIFS('Molecules_Positive ion mode'!N$4:N$390,'Molecules_Positive ion mode'!$G$4:$G$390,'Lipid class level'!$B8) -> 69715 | J8: =SUMIFS('Molecules_Positive ion mode'!O$4:O$390,'Molecules_Positive ion mode'!$G$4:$G$390,'Lipid class level'!$B8) -> 47613 | L8: =SUMIFS('Molecules_Positive ion mode'!Q$4:Q$390,'Molecules_Positive ion mode'!$G$4:$G$390,'Lipid class level'!$B8) -> 5749 | M8: =SUMIFS('Molecules_Positive ion mode'!R$4:R$390,'Molecules_Positive ion mode'!$G$4:$G$390,'Lipid class level'!$B8) -> 30987 | N8: =SUMIFS('Molecules_Positive ion mode'!S$4:S$390,'Molecules_Positive ion mode'!$G$4:$G$390,'Lipid class level'!$B8) -> 11226 | O8: =SUMIFS('Molecules_Positive ion mode'!T$4:T$390,'Molecules_Positive ion mode'!$G$4:$G$390,'Lipid class level'!$B8) -> 7258 | P8: =SUMIFS('Molecules_Positive ion mode'!U$4:U$390,'Molecules_Positive ion mode'!$G$4:$G$390,'Lipid class level'!$B8) -> 19959 | Q8: =SUMIFS('Molecules_Positive ion mode'!V$4:V$390,'Molecules_Positive ion mode'!$G$4:$G$390,'Lipid class level'!$B8) -> 18259 | R8: =SUMIFS('Molecules_Positive ion mode'!W$4:W$390,'Molecules_Positive ion mode'!$G$4:$G$390,'Lipid class level'!$B8) -> 12820 | T8: =SUMIFS('Molecules_Positive ion mode'!Y$4:Y$390,'Molecules_Positive ion mode'!$G$4:$G$390,'Lipid class level'!$B8) -> 776 | U8: =SUMIFS('Molecules_Positive ion mode'!Z$4:Z$390,'Molecules_Positive ion mode'!$G$4:$G$390,'Lipid class level'!$B8) -> 49161 | V8: =SUMIFS('Molecules_Positive ion mode'!AA$4:AA$390,'Molecules_Positive ion mode'!$G$4:$G$390,'Lipid class level'!$B8) -> 49078 | W8: =SUMIFS('Molecules_Positive ion mode'!AB$4:AB$390,'Molecules_Positive ion mode'!$G$4:$G$390,'Lipid class level'!$B8) -> 47600 | X8: =IFERROR(STDEV(U8:W8)/AVERAGE(U8:W8),0) -> 0.018066459 | Y8: =AVERAGE(D8:J8) -> 79497.857 | Z8: =AVERAGE(L8:R8) -> 15179.714 | AA8: =Z8/Y8 -> 0.19094495 | AB8: =TTEST(D8:J8,L8:R8,2,3) -> 0.00047460027 | AC8: =IF(AB8<0.001,"***",IF(AB8<0.01,"**",IF(AB8<0.05,"*","-"))) -> ***
